*** Settings ***
Resource          resource.txt
Suite Setup       Set Debug Log Level
Suite Teardown    Reset Log Level

*** Test Cases ***
Remote Traceback Is Shown In Log
    [Documentation]  FAIL My error message
    ...    LOG 1:1 FAIL My error message
    ...    LOG 1:2 DEBUG REGEXP: Traceback \\(most recent call last\\):
    ...    \\s+File "[\\w: /\\\\]+[^/\\\\]+ibrary.py", line .*
    ...    \\s+raise AssertionError\\(message\\)
    Failing    My error message

Remote Traceback With Multiple Entries
    [Documentation]  FAIL Finally failing
    ...    LOG 1:1 FAIL Finally failing
    ...    LOG 1:2 DEBUG REGEXP: Traceback \\(most recent call last\\):
    ...    .*
    ...    \\s+raise RuntimeError\\('Finally failing'\\)
    Failure Deeper

Local Traceback Is Not Shown In Log
    [Documentation]  FAIL Yet another error
    ...    LOG 1:1 FAIL Yet another error
    ...    LOG 1:2 DEBUG REGEXP: Traceback .*
    ...    LOG 1:3 NONE
    Failing    Yet another error

